Workbook

Sheet Quotation
H1: Quotation
B2: Address - Corporate HQ : Axestrack Software Solutions Pvt. Ltd., Office No.-19, 6th Floor, Jaipur Electronic Market, Near Riddhi Siddhi, Gopalpura bypass, Jaipur - 302018 , Rajasthan, India
B3: GSTIN | D3: 08AACCH0299P1Z1 | F3: QUOTE # | H3: DATE
B4: MSME No | D4: UDYAM-RJ-17-0051921 | F4: ABC/XY/YYMM## | H4: =TODAY() -> 45645
B5: Contact Person
B6: Phone | F6: Quote Validity : 15 days from submitted date
B7: Email Id
B9: CUSTOMER INFO
B10: Company Name | D10: Ashai India Glass Ltd.
B11: Address
B12: Contact Person | F12: Phone
B13: Email Id
B15: DESCRIPTION OF WORK
B16: <Sales SPOC to write description>
B17: S.No. | C17: items | G17: Type | I17: Amount
B18: 1 | C18: Hardware Cost | E18: Hardware BOQ Cost | G18: One tIme | I18: =ROUNDUP('Commercials (C)'!E37,0) -> 7769197
E19: Spares | G19: One tIme | I19: =ROUNDUP('Commercials (C)'!F37,0) -> 774108
B20: 2 | C20: Implementation Cost | E20: Configuration, Setup, Integration, Deployment & Training Cost | G20: One tIme | I20: =ROUNDUP(('Commercials (C)'!G37+'Commercials (C)'!H37),0) -> 1205358
B21: **Project Implementation Cost Per Plant | I21: =SUM(I18:I20) -> 9748663
B22: 3 | C22: Annual Subscription Fee | E22: Platform Subscription + PMO Cost + Support & Maintenance | G22: Per Month | I22: =ROUNDUP('Commercials (C)'!J42,0) -> 454079
B23: 4 | C23: AMC | E23: AMC from 2nd year onwards | G23: Per Year | I23: =ROUNDUP('Commercials (C)'!K42,0) -> 174261
B25: Please refer to the next page for Terms and Conditions & Notes
B27: Terms & Conditions
B28: • All the prices mentioned in proposal are in rupees and exclusive of GST. Taxes as applicable • Device ownership remains with Client • Trips are estimated based on received details; any formal change or upgrade in hardware specifications or features (beyond those installed during onboarding) will incur additional charges. • In the event of device loss, tampering, or theft, a charge of INR #### plus GST (per device) will be applied • The standard one-year hardware warranty period, as per OEM guidelines, will commence from the date of hardware delivery. • ERP integration costs are covered exclusively for the ##### plant. Additional ERP integration for any other plant will incur a separate charge of INR #### per plant • **Hardware and spare costs may differ from one plant to another depending on the plant layout and specific checkpoints. • The installation of RFID tags for 70,000 pallets will be an ongoing process that will continue even after the project go-live. Payment Terms: '• Payment will be on milestone basis • Milestone 1: 100% of Hardware cost with PO. • Milestone 2: 50% of implementation cost at the time of project kick-off. • Milestone 3: 50% of implementation cost at the time of Go-Live • The billing will be in advance for minimum ### on pro-rata basis. • 100% payments to be made within 15 days from the date of receipt of original or digitally signed invoice. In case of further delay, overdue charges of 1.5% per month will be charged • Billing validation/certification to be made within 7 days from the date of provisional bill submission.
B29: Project Exclusions
B30: • Data cleansing and data extraction from source system • Issues and bugs related to 3rd Party product or services or plugins • Customization related to 3rd party products • Civil work, Mounting poles, Power supply, LAN & wi-fi connectivity for hardware setup for the submitted proposal.
B31: Additional notes
B32: <Sales SPOC to write Additional notes, if any>
B33: Thanks for doing business with Axestrack Software Solution Pvt. Ltd.

Sheet Quotation BOQ
H1: Quotation
B2: Address - Corporate HQ : Axestrack Software Solutions Pvt. Ltd., Office No.-19, 6th Floor, Jaipur Electronic Market, Near Riddhi Siddhi, Gopalpura bypass, Jaipur - 302018 , Rajasthan, India
B3: GSTIN | D3: 08AACCH0299P1Z1 | F3: QUOTE # | H3: DATE
B4: MSME No | D4: UDYAM-RJ-17-0051921 | F4: =Quotation!F4 -> ABC/XY/YYMM## | H4: =Quotation!H4 -> 45645
B5: Contact Person | D5: =Quotation!D5 -> 0
B6: Phone | D6: =Quotation!D6 -> 0 | F6: Quote Validity : 15 days from submitted date
B7: Email Id | D7: =Quotation!D7 -> 0
B9: CUSTOMER INFO
B10: Company Name | D10: =Quotation!D10 -> Ashai India Glass Ltd.
B11: Address | D11: =Quotation!D11 -> 0
B12: Contact Person | D12: =Quotation!D12 -> 0 | F12: Phone | H12: =Quotation!H12 -> 0
B13: Email Id | D13: =Quotation!D13 -> 0
B15: HARDWARE BOQ
B16: S.No. | C16: Hardware | F16: Count | G16: Spares | I16: Total
B17: 1 | C17: ='Total Hardware'!B3 -> RFID Reader | F17: =VLOOKUP(C17,'Total Hardware'!$B$3:$F$6,2,FALSE) -> 20 | G17: =VLOOKUP(C17,'Total Hardware'!$B$3:$F$6,5,FALSE) -> 4 | I17: =F17+G17 -> 24
B18: 2 | C18: ='Total Hardware'!B4 -> Handheld RFID Reader | F18: =VLOOKUP(C18,'Total Hardware'!$B$3:$F$6,2,FALSE) -> 6 | G18: =VLOOKUP(C18,'Total Hardware'!$B$3:$F$6,5,FALSE) -> 3 | I18: =F18+G18 -> 9
B19: 4 | C19: ='Total Hardware'!B5 -> Desktop | F19: =VLOOKUP(C19,'Total Hardware'!$B$3:$F$6,2,FALSE) -> 1 | G19: =VLOOKUP(C19,'Total Hardware'!$B$3:$F$6,5,FALSE) -> 0 | I19: =F19+G19 -> 1
B20: 3 | C20: ='Total Hardware'!B6 -> RFID Tag | F20: =VLOOKUP(C20,'Total Hardware'!$B$3:$F$6,2,FALSE) -> 140000 | G20: =VLOOKUP(C20,'Total Hardware'!$B$3:$F$6,5,FALSE) -> 10000 | I20: =F20+G20 -> 150000
B21: Total | F21: =SUM(F17:F20) -> 140027 | G21: =SUM(G17:H20) -> 10007 | I21: =SUM(I17:I20) -> 150034
B23: Additional notes
B24: <Sales SPOC to write Additional notes, if any>
B25: Thanks for doing business with Axestrack Software Solution Pvt. Ltd.

Sheet Quote Nomeclature
B2: Quote no Format
B3: ABC/XY/YYMM##
B5: ABC | C5: Client name short Form like Hindalco Industries Limited will be HIL
B6: XY | C6: Axestrack Sales SPOC Intials
B7: YY | C7: Year
B8: MM | C8: Month
B9: ## | C9: Quote send by Sales SPOC in that particular month, quote nos. should be start from 11

Sheet Commercials (C)
B2: Customer | D2: Ashai India Glass Ltd.
B3: Date | D3: =TODAY() -> 45645
B4: Contract Year | D4: 3
B5: AMC Cost | D5: 0.23
B6: Hardware Transportation Cost | D6: 0.05
B7: ERP Integration Cost | D7: 350000 | M7: Pallet | N7: 70000 | P7: =3500*15000 -> 52500000
B8: Software Subscription Cost/month | D8: 350000 | M8: Per Pallet Cost per month | N8: =N30/D4/12/N7 -> 10.493648 | P8: =10*70000*12 -> 8400000
P9: =P8/P7 -> 0.16
B10: Model | C10: Items | E10: Details | F10: Type | G10: Unit Cost | H10: Nos. of years | I10: Landed Cost to Axestrack | J10: Contingency / Risk Margin | K10: Cost to Axestrack (with Contingency) | L10: Margin | M10: Unit price on Margin | N10: Cost for Customer
B11: One Time Cost | C11: Hardware Cost | D11: Hardware BOQ Cost | E11: Hardware - BOQ | F11: One Time | I11: ='Total Hardware'!E7 -> 5801000 | J11: 0.02 | K11: =I11/(1-J11) -> 5919387.8 | L11: 0.2 | M11: =IF(H11=0,(K11/(1-L11)),(K11/H11)/(1-L11)) -> 7399234.7 | N11: =K11/(1-L11) -> 7399234.7
E12: Hardware Transportation Cost | F12: One Time | I12: =I11*D6 -> 290050 | J12: 0.02 | K12: =I12/(1-J12) -> 295969.39 | L12: 0.2 | M12: =IF(H12=0,(K12/(1-L12)),(K12/H12)/(1-L12)) -> 369961.73 | N12: =K12/(1-L12) -> 369961.73
E13: Haedware BOQ Cost | I13: =SUM(I11:I12) -> 6091050 | K13: =SUM(K11:K12) -> 6215357.1 | M13: =SUM(M11:M12) -> 7769196.4 | N13: =SUM(N11:N12) -> 7769196.4
D14: Spares BOQ Cost | E14: Spares - BOQ | F14: One Time | I14: ='Total Hardware'!G7 -> 578000 | J14: 0.02 | K14: =I14/(1-J14) -> 589795.92 | L14: 0.2 | M14: =IF(H14=0,(K14/(1-L14)),(K14/H14)/(1-L14)) -> 737244.9 | N14: =K14/(1-L14) -> 737244.9
E15: Spares Transportation Cost | F15: One Time | I15: =I14*D6 -> 28900 | J15: 0.02 | K15: =I15/(1-J15) -> 29489.796 | L15: 0.2 | M15: =IF(H15=0,(K15/(1-L15)),(K15/H15)/(1-L15)) -> 36862.245 | N15: =K15/(1-L15) -> 36862.245
E16: Spares BOQ Cost | I16: =SUM(I14:I15) -> 606900 | K16: =SUM(K14:K15) -> 619285.71 | M16: =SUM(M14:M15) -> 774107.14 | N16: =SUM(N14:N15) -> 774107.14
D17: Total Hardware Cost | I17: =I13+I16 -> 6697950 | K17: =K13+K16 -> 6834642.9 | M17: =M13+M16 -> 8543303.6 | N17: =N13+N16 -> 8543303.6
C18: Implementation Cost | D18: Installation, Training & Configuration | E18: Phase -1 + Hypercare cost+ Transition | F18: One Time | I18: ='Manpower-PM Cost'!H10+'Manpower-PM Cost'!Z11+'Manpower-PM Cost'!Z28 -> 595000 | J18: 0.02 | K18: =I18/(1-J18) -> 607142.86 | L18: 0.2 | M18: =IF(H18=0,(K18/(1-L18)),(K18/H18)/(1-L18)) -> 758928.57 | N18: =K18/(1-L18) -> 758928.57
D19: ERP Integration | E19: ERP Integration | F19: One Time | I19: =D7 -> 350000 | J19: 0.02 | K19: =I19/(1-J19) -> 357142.86 | L19: 0.2 | M19: =IF(H19=0,(K19/(1-L19)),(K19/H19)/(1-L19)) -> 446428.57 | N19: =K19/(1-L19) -> 446428.57
D20: Total Installation, Setup & API Development Cost | I20: =SUM(I18:I19) -> 945000 | K20: =SUM(K18:K19) -> 964285.71 | M20: =SUM(M18:M19) -> 1205357.1 | N20: =SUM(N18:N19) -> 1205357.1
C21: One Time Cost | I21: =I17+I20 -> 7642950 | K21: =K17+K20 -> 7798928.6 | M21: =M17+M20 -> 9748660.7 | N21: =N17+N20 -> 9748660.7
C22: Annual Subscription fee | D22: Onsite Manpower, Project Management, Support & Maintenance | E22: Onsite Manpower | F22: Per Year | G22: ='Manpower-PM Cost'!AI10 -> 960000 | H22: =(((D4*12)+'AMC & months'!C14)-('AMC & months'!C14+'AMC & months'!C15))/12 -> 2.8333333 | I22: =G22*H22 -> 2720000 | J22: 0.02 | K22: =I22/(1-J22) -> 2775510.2 | L22: 0.2 | M22: =IF(H22=0,(K22/(1-L22)),(K22/H22)/(1-L22)*H22/$D$4) -> 1156462.6 | N22: =K22/(1-L22) -> 3469387.8 | O22: =M22*3 -> 3469387.8 | P22: =O22=N22 -> TRUE
E23: PMO Cost | F23: Per Year | G23: ='Manpower-PM Cost'!AT10 -> 72500 | H23: =D4 -> 3 | I23: =G23*H23 -> 217500 | J23: 0.02 | K23: =I23/(1-J23) -> 221938.78 | L23: 0.2 | M23: =IF(H23=0,(K23/(1-L23)),(K23/H23)/(1-L23)*H23/$D$4) -> 92474.49 | N23: =K23/(1-L23) -> 277423.47
D24: Total Installation, Setup & API Development Cost | K24: =SUM(K22:K23) -> 2997449 | M24: =SUM(M22:M23) -> 1248937.1 | N24: =SUM(N22:N23) -> 3746811.2
D25: Platform Subscription Fee | E25: Platform Subscription Fee | F25: Per Year | G25: =D8*12 -> 4200000 | H25: =D4 -> 3 | I25: =G25*H25 -> 12600000 | J25: 0 | K25: =I25/(1-J25) -> 12600000 | L25: 0 | M25: =IF(H25=0,(K25/(1-L25)),(K25/H25)/(1-L25)) -> 4200000 | N25: =K25/(1-L25) -> 12600000
D26: Total Installation, Setup & API Development Cost | K26: =SUM(K25) -> 12600000 | M26: =SUM(M25) -> 4200000 | N26: =SUM(N25) -> 12600000
C27: Subscription Fee | K27: =K24+K26 -> 15597449 | M27: =M24+M26 -> 5448937.1 | N27: =N24+N26 -> 16346811
B28: AMC | C28: AMC | D28: AMC | E28: AMC from 2nd Year onwards | F28: Per Year | G28: =('Total Hardware'!H8)*D5 -> 136620 | H28: =D4-1 -> 2 | I28: =G28*H28 -> 273240 | J28: 0.02 | K28: =I28/(1-J28) -> 278816.33 | L28: 0.2 | M28: =IF(H28=0,(K28/(1-L28)),(K28/H28)/(1-L28)*H28/($D$4-1)) -> 174260.2 | N28: =K28/(1-L28) -> 348520.41
C29: AMC | K29: =SUM(K28:K28) -> 278816.33 | M29: =SUM(M28:M28) -> 174260.2 | N29: =SUM(N28:N28) -> 348520.41 | O29: =M29*H28 -> 348520.41 | P29: =O29=N29 -> TRUE
B30: Total Cost of the Project Implementation & Support + AMC | K30: =K21+K27+K29 -> 23675194 | L30: =1-K30/N30 -> 0.10470425 | N30: =N21+N27+N29 -> 26443992
C33: Quote Values
D34: =D4 -> 3 | H34: 0 | K34: =D4-1 -> 2
I35: =N27 -> 16346811 | K35: =N29 -> 348520.41
D36: %age of subcription | E36: Hardware Cost | F36: Spare Cost | G36: Implementation Cost | H36: Subscription Fee with Impl. | I36: Subscription Fee per year | J36: Subscription Fee per month post impl. | K36: AMC | L36: Total | M36: %
C37: Y1 | D37: =100%/D34 -> 0.33333333 | E37: =N13 -> 7769196.4 | F37: =N16 -> 774107.14 | G37: =N20 -> 1205357.1 | H37: =H34*I35 -> 0 | I37: =D37*($I$35-$H$37) -> 5448937.1 | J37: =I37/12 -> 454078.09 | L37: =SUM(E37:K37)-J37 -> 15197598 | M37: =L37/$L$43 -> 0.5747089
C38: Y2 | D38: =IF($D$34>1,(100%-$D$37)/($D$34-1),0) -> 0.33333333 | I38: =D38*($I$35-$H$37) -> 5448937.1 | J38: =I38/12 -> 454078.09 | K38: =IF(D38=0,0,$K$35/$K$34) -> 174260.2 | L38: =SUM(E38:K38)-J38 -> 5623197.3 | M38: =L38/$L$43 -> 0.21264555
C39: Y3 | D39: =IF($D$34>2,(100%-$D$37)/($D$34-1),0) -> 0.33333333 | I39: =D39*($I$35-$H$37) -> 5448937.1 | J39: =I39/12 -> 454078.09 | K39: =IF(D39=0,0,$K$35/$K$34) -> 174260.2 | L39: =SUM(E39:K39)-J39 -> 5623197.3 | M39: =L39/$L$43 -> 0.21264555
C40: Y4 | D40: =IF($D$34>3,(100%-$D$37)/($D$34-1),0) -> 0 | I40: =D40*($I$35-$H$37) -> 0 | J40: =I40/12 -> 0 | K40: =IF(D40=0,0,$K$35/$K$34) -> 0 | L40: =SUM(E40:K40)-J40 -> 0 | M40: =L40/$L$43 -> 0
C41: Y5 | D41: =IF($D$34>4,(100%-$D$37)/($D$34-1),0) -> 0 | I41: =D41*($I$35-$H$37) -> 0 | J41: =I41/12 -> 0 | K41: =IF(D41=0,0,$K$35/$K$34) -> 0 | L41: =SUM(E41:K41)-J41 -> 0 | M41: =L41/$L$43 -> 0
J42: =AVERAGEIF(J37:J41,">0") -> 454078.09 | K42: =AVERAGEIF(K37:K41,">0") -> 174260.2
E43: =SUM(E37:H37) -> 9748660.7 | L43: =SUM(L37:L41) -> 26443992 | M43: =L43/$L$43 -> 1
...

Sheet Sheet1
B3: type of heads | C3: Headers
B4: hardware | C4: Rfid reader | D4: Handheld | E4: tags
B5: Transportation cost
B6: Spares
B7: Spares Trasnporation cost
B8: Impl. Cots | C8: Installation, Training & Configuration | D8: ERP Integration
B9: Annual Subscription fee | C9: Onsite Manpower | D9: PMO Cost | E9: Platform Subscription Fee
B10: AMC | C10: AMC from 2nd year

Sheet Manpower-PM Cost
B2: Implementation Cost | K2: Hyper Care + Transition Cost | AC2: Onsite Resource Cost Post Impl & Hypercare | AL2: Project Management Cost (d)
C4: Phase 1 | L4: Hypercare | AD4: Onsite Manpower | AM4: Project Management Cost (d)
C5: Installation, Training & Configuration Cost for phase 1 (a) | L5: Hypercare (b) | AD5: Post Hyper care Onsite Manpower (c) | AM5: Annual Project Management Cost (d)
C6: Type of Manpower | D6: Count per shift | E6: Nos. of shifts | F6: Cost per Resource per month | G6: Duration in Months | H6: Total | L6: Type of Manpower | M6: Cost per Resource per month | N6: Shift | O6: M1 | P6: M2 | Q6: M3 | R6: M4 | S6: M5 | T6: M6 | U6: M7 | V6: M8 | W6: M9 | X6: M10 | Y6: M11 | Z6: M12 | AD6: Type of Manpower | AE6: Count per shift | AF6: Nos. of shifts | AG6: Cost per Resource per month | AH6: Duration in Months | AI6: Total | AM6: Type of Manpower | AN6: Type | AO6: Travel Allowance | AP6: Travel Cost | AQ6: Stay Cost per Day | AR6: Days per trip | AS6: Frequency (Annually) | AT6: Total
C7: PM | D7: 0.5 | E7: 1 | F7: 100000 | G7: 2 | H7: =D7*E7*F7*G7 -> 100000 | L7: PM | M7: 100000 | N7: 1 | O7: 0 | P7: 0 | Q7: 0.5 | R7: 0 | S7: 0 | T7: 0 | U7: 0 | V7: 0 | W7: 0 | X7: 0 | Y7: 0 | Z7: 0 | AD7: PM/ Sr. CS | AE7: 0 | AF7: 0 | AG7: 100000 | AH7: 12 | AI7: =AE7*AF7*AG7*AH7 -> 0 | AM7: Project Manager | AN7: Per Year | AO7: 2000 | AP7: 4500 | AQ7: 4500 | AR7: 1 | AS7: 4 | AT7: =(AS7*AR7*AO7)+(AP7*AS7)+(AQ7*AR7*AS7) -> 44000
C8: Hardware Engineers | D8: 1 | E8: 1 | F8: 60000 | G8: 2 | H8: =D8*E8*F8*G8 -> 120000 | L8: Hardware Engineers | M8: 60000 | N8: 1 | O8: 0 | P8: 0 | Q8: 1 | R8: 0 | S8: 0 | T8: 0 | U8: 0 | V8: 0 | W8: 0 | X8: 0 | Y8: 0 | Z8: 0 | AD8: Support Engineers | AE8: 2 | AF8: 2 | AG8: 20000 | AH8: 12 | AI8: =AE8*AF8*AG8*AH8 -> 960000 | AM8: Project Coordinator | AN8: Per Year | AO8: 0 | AP8: 0 | AQ8: 0 | AR8: 0 | AS8: 0 | AT8: =(AS8*AR8*AO8)+(AP8*AS8)+(AQ8*AR8*AS8) -> 0
C9: Software Engineers | D9: 1 | E9: 1 | F9: 75000 | G9: 2 | H9: =D9*E9*F9*G9 -> 150000 | L9: Software Engineers | M9: 75000 | N9: 1 | O9: 0 | P9: 0 | Q9: 1 | R9: 0 | S9: 0 | T9: 0 | U9: 0 | V9: 0 | W9: 0 | X9: 0 | Y9: 0 | Z9: 0 | AD9: MIS Support | AE9: 0 | AF9: 0 | AG9: 35000 | AH9: 12 | AI9: =AE9*AF9*AG9*AH9 -> 0 | AM9: Misc Travel | AN9: Per Year | AO9: 1500 | AP9: 4500 | AQ9: 3500 | AR9: 1 | AS9: 3 | AT9: =(AS9*AR9*AO9)+(AP9*AS9)+(AQ9*AR9*AS9) -> 28500
D10: =D7*E7+D8*E8+D9*E9 -> 2.5 | G10: Total | H10: =SUM(H7:H9) -> 370000 | O10: =(O7*$M$7*$N$7)+(O8*$M$8*$N$8)+(O9*$M$9*$N$9) -> 0 | P10: =(P7*$M$7*$N$7)+(P8*$M$8*$N$8)+(P9*$M$9*$N$9) -> 0 | Q10: =(Q7*$M$7*$N$7)+(Q8*$M$8*$N$8)+(Q9*$M$9*$N$9) -> 185000 | R10: =(R7*$M$7*$N$7)+(R8*$M$8*$N$8)+(R9*$M$9*$N$9) -> 0 | S10: =(S7*$M$7*$N$7)+(S8*$M$8*$N$8)+(S9*$M$9*$N$9) -> 0 | T10: =(T7*$M$7*$N$7)+(T8*$M$8*$N$8)+(T9*$M$9*$N$9) -> 0 | U10: =(U7*$M$7*$N$7)+(U8*$M$8*$N$8)+(U9*$M$9*$N$9) -> 0 | V10: =(V7*$M$7*$N$7)+(V8*$M$8*$N$8)+(V9*$M$9*$N$9) -> 0 | ... Z10: =(Z7*$M$7*$N$7)+(Z8*$M$8*$N$8)+(Z9*$M$9*$N$9) -> 0 | AE10: =AE7*AF7+AE8*AF8+AE9*AF9 -> 4 | AH10: Total | AI10: =SUM(AI7:AI9) -> 960000 | AS10: Total | AT10: =SUM(AT7:AT9) -> 72500
Y11: Hypercare Cost | Z11: =SUM(O10:Z10) -> 185000
C13: Current Equipments | D13: Count | E13: Productivity per resource | F13: Resources Required | J13: Planned Equipments | L13: Count | M13: Productivity per resource | N13: Resources Required
C14: Machines | D14: 47 | E14: 6 | F14: =ROUND(D14/E14,0) -> 8 | J14: Machines | L14: 0 | M14: =$E14 -> 6 | N14: =ROUND(L14/$E$14,0) -> 0
C15: Gate Lanes | D15: 40 | E15: 7 | F15: =ROUND(D15/E15,0) -> 6 | J15: Gate Lanes | L15: 0 | M15: =$E15 -> 7 | N15: =ROUND(L15/$E$15,0) -> 0
C16: Vehicles | D16: 810 | E16: 120 | F16: =ROUND(D16/E16,0) -> 7 | J16: Vehicles | L16: 0 | M16: =$E16 -> 120 | N16: =ROUND(L16/$E$16,0) -> 0
E17: Onsite | F17: =SUM(F14:F16) -> 21 | M17: =$E17 -> Onsite | N17: =SUM(N14:N16) -> 0
E18: MIS | F18: =ROUND(F17/8,0) -> 3 | M18: =$E18 -> MIS | N18: =ROUND(N17/8,0) -> 0
E19: Total | F19: =F17+F18 -> 24 | M19: =$E19 -> Total | N19: =N17+N18 -> 0
C21: Phase 2 | L21: Transition Onsite Manpower
C22: Installation, Training & Configuration Cost for phase 2 (a) | L22: Transition (b)
C23: Type of Manpower | D23: Count per shift | E23: Nos. of shifts | F23: Cost per Resource per month | G23: Duration in Months | H23: Total | L23: Type of Manpower | M23: Cost per Resource per month | N23: Shift | O23: M1 | P23: M2 | Q23: M3 | R23: M4 | S23: M5 | T23: M6 | U23: M7 | V23: M8 | W23: M9 | X23: M10 | Y23: M11 | Z23: M12
C24: PM | D24: 0 | E24: 0 | F24: 100000 | G24: 0 | H24: =D24*E24*F24*G24 -> 0 | L24: PM/ Sr. CS | M24: 100000 | N24: 0 | O24: 0 | P24: 0 | Q24: 0 | R24: 0 | S24: 0 | T24: 0 | U24: 0 | V24: 0 | W24: 0 | X24: 0 | Y24: 0 | Z24: 0
C25: Hardware Engineers | D25: 0 | E25: 0 | F25: 60000 | G25: 0 | H25: =D25*E25*F25*G25 -> 0 | L25: Support Engineers | M25: 20000 | N25: 2 | O25: 0 | P25: 0 | Q25: 1 | R25: 0 | S25: 0 | T25: 0 | U25: 0 | V25: 0 | W25: 0 | X25: 0 | Y25: 0 | Z25: 0
C26: Software Engineers | D26: 0 | E26: 0 | F26: 75000 | G26: 0 | H26: =D26*E26*F26*G26 -> 0 | L26: MIS Support | M26: 35000 | N26: 0 | O26: 0 | P26: 0 | Q26: 0 | R26: 0 | S26: 0 | T26: 0 | U26: 0 | V26: 0 | W26: 0 | X26: 0 | Y26: 0 | Z26: 0
D27: =D24*E24+D25*E25+D26*E26 -> 0 | G27: Total | H27: =SUM(H24:H26) -> 0 | O27: =(O24*$M$24*$N$24)+(O25*$M$25*$N$25)+(O26*$M$26*$N$26) -> 0 | P27: =(P24*$M$24*$N$24)+(P25*$M$25*$N$25)+(P26*$M$26*$N$26) -> 0 | Q27: =(Q24*$M$24*$N$24)+(Q25*$M$25*$N$25)+(Q26*$M$26*$N$26) -> 40000 | R27: =(R24*$M$24*$N$24)+(R25*$M$25*$N$25)+(R26*$M$26*$N$26) -> 0 | S27: =(S24*$M$24*$N$24)+(S25*$M$25*$N$25)+(S26*$M$26*$N$26) -> 0 | T27: =(T24*$M$24*$N$24)+(T25*$M$25*$N$25)+(T26*$M$26*$N$26) -> 0 | U27: =(U24*$M$24*$N$24)+(U25*$M$25*$N$25)+(U26*$M$26*$N$26) -> 0 | V27: =(V24*$M$24*$N$24)+(V25*$M$25*$N$25)+(V26*$M$26*$N$26) -> 0 | ... Z27: =(Z24*$M$24*$N$24)+(Z25*$M$25*$N$25)+(Z26*$M$26*$N$26) -> 0
Y28: Transitione Cost | Z28: =SUM(O27:Z27) -> 40000
O29: =SUMPRODUCT($N$7:$N$9,O7:O9)+(SUMPRODUCT($N$24:$N$26,O24:O26)) -> 0 | P29: =SUMPRODUCT($N$7:$N$9,P7:P9)+(SUMPRODUCT($N$24:$N$26,P24:P26)) -> 0 | Q29: =SUMPRODUCT($N$7:$N$9,Q7:Q9)+(SUMPRODUCT($N$24:$N$26,Q24:Q26)) -> 4.5 | R29: =SUMPRODUCT($N$7:$N$9,R7:R9)+(SUMPRODUCT($N$24:$N$26,R24:R26)) -> 0 | S29: =SUMPRODUCT($N$7:$N$9,S7:S9)+(SUMPRODUCT($N$24:$N$26,S24:S26)) -> 0 | T29: =SUMPRODUCT($N$7:$N$9,T7:T9)+(SUMPRODUCT($N$24:$N$26,T24:T26)) -> 0 | U29: =SUMPRODUCT($N$7:$N$9,U7:U9)+(SUMPRODUCT($N$24:$N$26,U24:U26)) -> 0 | V29: =SUMPRODUCT($N$7:$N$9,V7:V9)+(SUMPRODUCT($N$24:$N$26,V24:V26)) -> 0 | ... Z29: =SUMPRODUCT($N$7:$N$9,Z7:Z9)+(SUMPRODUCT($N$24:$N$26,Z24:Z26)) -> 0 | AG29: `

Sheet AMC & months
C2: Months
B3: Implementation Period | C3: 1
B4: Hypercare Period | C4: 2
B5: Hardware Delivery Month | C5: 1
B6: Project Period | C6: ='Commercials (C)'!D4*12+C3 -> 37
B7: OEM Warranty Till | C7: =C5+12 -> 13
A8: AMC 1 | B8: AMC 2nd Year till | C8: =C7+12 -> 25
A9: AMC 2 | B9: AMC 3rd Year till | C9: =C8+12 -> 37
B10: Remaining month | C10: =C6-C9 -> 0
A12: Manpower Month post implementation
C13: Months
B14: Implementation Period | C14: =C3 -> 1
B15: Hypercare Period | C15: =C4 -> 2
B16: Project Period | C16: =C6 -> 37
A17: Manpower 1 | B17: 1st year | C17: =C14+12 -> 13
A18: Manpower 2 | B18: 2nd year | C18: =C17+12 -> 25
A19: Manpower 3 | B19: 3rd year | C19: =C18+12 -> 37
B21: Manpower Period post hypercare | C21: =C16-C15-C14 -> 34

Sheet Total Hardware
F1: 0.2
A2: Sr. No. | B2: Hardware | C2: Count | D2: Unit Price | E2: Cost of Hardware | F2: Spares | G2: Cost of Spares | H2: Total | I2: Total
A3: 1 | B3: RFID Reader | C3: =SUMIF(BOQ!$C$3:$F$16,'Total Hardware'!B3,BOQ!$E$3:$E$16) -> 20 | D3: =VLOOKUP(B3,Master!$A$2:$B$5,2,FALSE) -> 0 | E3: =C3*D3 -> 0 | F3: 4 | G3: =F3*D3 -> 0 | H3: =E3+G3 -> 0 | I3: =C3+F3 -> 24
A4: =A3+1 -> 2 | B4: Handheld RFID Reader | C4: =SUMIF(BOQ!$C$3:$F$16,'Total Hardware'!B4,BOQ!$E$3:$E$16) -> 6 | D4: =VLOOKUP(B4,Master!$A$2:$B$5,2,FALSE) -> 66000 | E4: =C4*D4 -> 396000 | F4: 3 | G4: =F4*D4 -> 198000 | H4: =E4+G4 -> 594000 | I4: =C4+F4 -> 9
A5: 4 | B5: Desktop | C5: =SUMIF(BOQ!$C$3:$F$16,'Total Hardware'!B5,BOQ!$E$3:$E$16) -> 1 | D5: =VLOOKUP(B5,Master!$A$2:$B$5,2,FALSE) -> 85000 | E5: =C5*D5 -> 85000 | F5: 0 | G5: =F5*D5 -> 0 | H5: =E5+G5 -> 85000 | I5: =C5+F5 -> 1
A6: 3 | B6: RFID Tag | C6: =SUMIF(BOQ!$C$3:$F$16,'Total Hardware'!B6,BOQ!$E$3:$E$16) -> 140000 | D6: =VLOOKUP(B6,Master!$A$2:$B$5,2,FALSE) -> 38 | E6: =C6*D6 -> 5320000 | F6: 10000 | G6: =F6*D6 -> 380000 | H6: =E6+G6 -> 5700000 | I6: =C6+F6 -> 150000
B7: Total | C7: =SUM(C3:C6) -> 140027 | E7: =SUM(E3:E6) -> 5801000 | F7: =SUM(F3:F6) -> 10007 | G7: =SUM(G3:G6) -> 578000 | H7: =SUM(H3:H6) -> 6379000 | I7: =SUM(I3:I6) -> 150034
H8: =H3+H4 -> 594000
B9: This is formula driven sheet. Only update the spares Count
B10: Please update the BOQ sheet for other fields

Sheet BOQ
A2: Stage | B2: Location/Machine | C2: Hardware | D2: Unit Price | E2: Quantity per Check Point | F2: Total | G2: Remarks
B3: Unloading Area | C3: Handheld RFID Reader | D3: =_xlfn.IFNA(VLOOKUP(C3,Master!$A$2:$B$5,2,FALSE),0) -> 66000 | E3: 1 | F3: =D3*E3 -> 66000
B4: Pallet Area In | C4: RFID Reader | D4: =_xlfn.IFNA(VLOOKUP(C4,Master!$A$2:$B$5,2,FALSE),0) -> 0 | E4: 4 | F4: =D4*E4 -> 0
B5: Pallat To Maintenance Area In/Out | C5: RFID Reader | D5: =_xlfn.IFNA(VLOOKUP(C5,Master!$A$2:$B$5,2,FALSE),0) -> 0 | E5: 4 | F5: =D5*E5 -> 0
B6: Maintenance Area Out | C6: RFID Reader | D6: =_xlfn.IFNA(VLOOKUP(C6,Master!$A$2:$B$5,2,FALSE),0) -> 0 | E6: 4 | F6: =D6*E6 -> 0
B7: Gate Out | C7: Handheld RFID Reader | D7: =_xlfn.IFNA(VLOOKUP(C7,Master!$A$2:$B$5,2,FALSE),0) -> 66000 | E7: 1 | F7: =D7*E7 -> 66000
B8: WH Gate In | C8: Handheld RFID Reader | D8: =_xlfn.IFNA(VLOOKUP(C8,Master!$A$2:$B$5,2,FALSE),0) -> 66000 | E8: 1 | F8: =D8*E8 -> 66000
B9: WH - 1 Gate In/Out | C9: RFID Reader | D9: =_xlfn.IFNA(VLOOKUP(C9,Master!$A$2:$B$5,2,FALSE),0) -> 0 | E9: 4 | F9: =D9*E9 -> 0
B10: WH - 1 Gate In/Out | C10: Handheld RFID Reader | D10: =_xlfn.IFNA(VLOOKUP(C10,Master!$A$2:$B$5,2,FALSE),0) -> 66000 | E10: 1 | F10: =D10*E10 -> 66000
B11: WH - 2 Gate In/Out | C11: RFID Reader | D11: =_xlfn.IFNA(VLOOKUP(C11,Master!$A$2:$B$5,2,FALSE),0) -> 0 | E11: 4 | F11: =D11*E11 -> 0
B12: WH - 2 Gate In/Out | C12: Handheld RFID Reader | D12: =_xlfn.IFNA(VLOOKUP(C12,Master!$A$2:$B$5,2,FALSE),0) -> 66000 | E12: 1 | F12: =D12*E12 -> 66000
B13: WH Gate Out | C13: Handheld RFID Reader | D13: =_xlfn.IFNA(VLOOKUP(C13,Master!$A$2:$B$5,2,FALSE),0) -> 66000 | E13: 1 | F13: =D13*E13 -> 66000
C14: Desktop | D14: =_xlfn.IFNA(VLOOKUP(C14,Master!$A$2:$B$5,2,FALSE),0) -> 85000 | E14: 1 | F14: =D14*E14 -> 85000
B15: Other | C15: RFID Tag | D15: =_xlfn.IFNA(VLOOKUP(C15,Master!$A$2:$B$5,2,FALSE),0) -> 38 | E15: =70000*2 -> 140000 | F15: =D15*E15 -> 5320000
D16: =_xlfn.IFNA(VLOOKUP(C16,Master!$A$2:$B$5,2,FALSE),0) -> 0 | F16: =D16*E16 -> 0
F17: =SUM(F3:F16) -> 5801000

Sheet Master
A1: Equipment | B1: Cost
A2: RFID Reader | B2: 0 | C2: 27000
A3: Handheld RFID Reader | B3: 66000
A4: Desktop | B4: 85000
A5: RFID Tag | B5: 38
A7: Location
A8: Gate In
A9: Unloading Area
A10: Pallet Area In
A11: Pallat To Maintenance Area In/Out
A12: Maintenance Area Out
A13: Gate Out
A14: WH Gate In
A15: WH - 1 Gate In/Out
A16: WH - 2 Gate In/Out
A17: WH Gate Out
A18: Other
