Workbook

Sheet Sheet3
A3: Row Labels | B3: Sum of Total Hardware
A4: ANPR Camera | B4: 20
A5: AT Controller | B5: 18
A6: Biometric Device | B6: 20
A7: Boom Barrier | B7: 38
A8: Handheld RFID Reader | B8: 4
A9: Industrial Grade Tablet | B9: 14
A10: LED Display | B10: 30
A11: PA System | B11: 24
A12: Printer | B12: 6
A13: Proximity Sensor | B13: 36
A14: RFID Reader | B14: 38
A15: Smart Camera | B15: 40
... A18: Grand Total | B18: 315

Sheet Commercials Final
A2: Items | B2: Details | C2: Type | D2: Total Cost
A3: Hardware Cost | B3: Hardware - Mining Automation | C3: One Time | D3: 12592000
B4: Total Hardware Cost | C4: One Time | D4: =D3 -> 12592000
A5: Implementation Cost | B5: Installation, Training & Configuration and Hypercare | C5: One Time | D5: ='Software charges'!B4+'Software charges'!B5 -> 2680000
B6: ERP and I3MS Integration | C6: One Time | D6: =1700000+'Software charges'!B3 -> 2500000
B7: Total Installation, Setup,Hyper Care & API Development Cost | C7: One Time | D7: =SUM(D5:D6) -> 5180000
B8: Total One Time Cost | D8: =D4+D7 -> 17772000
A9: AMC | B9: AMC Cost from 2nd year( for Two years) | D9: 7400000
A10: Opex - Subscription fee | B10: Subscription for CPL, TMS, Track and Trace, Command centre Interface | C10: Opex- Per ton cost in Rs. | D10: 0.69
A11: Other Charges | B11: GPS per device cost | D11: 1500
B12: Maintenance cost from second year per device | D12: 600
B13: Manpower Management Cost per head per month ( in addition to the mines labour law) | D13: 3000
A14: Note: Above commercials are based on Minimum agreed billing of 11 MTPA. | F14: `

Sheet Commercials
A1: Customer | C1: AMNS Mines
A2: Date
A3: Contract Year | C3: 3 | K3: Platfor subscription | L3: =I22 -> 14400000
A4: AMC Cost | C4: 0.25 | D4: Second year onwards | K4: ERP Integration | L4: =I18 -> 600000
A5: Hardware Transportation Cost | C5: 0.05 | K5: Implementation | L5: =SUM('Manpower Cost'!T18:T19) -> 2200000
A6: Software Subscription cost per month | C6: 400000 | K6: Hypercare | L6: 480000
K7: Operations | L7: =(660000*2.5)+('Manpower Cost'!S8*3) -> 1923000
A8: ERP and Third party Integration | C8: 600000 | D8: <10 API | K8: Command centre | L8: =I27 -> 1800000
L9: =SUM(L3:L8) -> 21403000
K10: Track & Trace Per Trip | L10: RS.35/-
A12: Model | B12: Items | C12: Details | D12: Type | E12: Unit Cost | F12: Duration | G12: Total Cost to Axestrack for 3 years | H12: Margin | I12: Cost for 3 Years
A13: One Time Cost | B13: Hardware Cost | C13: Hardware - Mining Automation | D13: One Time | G13: =Hardware!H17 -> 17072600 | I13: =G13/(1-H13) -> 17072600
C14: Transportation Cost | D14: One Time | G14: =G13*$C$5 -> 853630 | I14: =G14/(1-H14) -> 853630
C15: Total Hardware Cost | G15: =SUM(G13:G14) -> 17926230 | I15: =SUM(I13:I14) -> 17926230 | M15: =16000*1.25 -> 20000
B16: Implementation Cost | C16: Installation, Training & Configuration | D16: One Time | G16: ='Manpower Cost'!G8 -> 2200000 | I16: =G16/(1-H16) -> 2200000 | J16: Travel, installation
C17: Hypercare- Onsite Manpower, Project Management, Support & Maintenance | D17: One Time | G17: ='Manpower Cost'!G18 -> 480000 | I17: =G17/(1-H17) -> 480000 | J17: Hyper care
C18: ERP Integration | D18: One Time | G18: =C8 -> 600000 | I18: =G18/(1-H18) -> 600000
C19: Total Installation, Setup,Hyper Care & API Development Cost | G19: =SUM(G16:G18) -> 3280000 | I19: =SUM(I16:I18) -> 3280000
D20: Total One Time Cost | G20: =G15+G19 -> 21206230 | I20: =I15+I19 -> 21206230
C21: AMC Cost from 2nd year | D21: Per Year | E21: 3700000 | F21: 2 | G21: 7400000 | I21: =G21 -> 7400000
B22: Annual Subscription fee | C22: Platform Subscription Fee | D22: Per Year | E22: =C6*12 -> 4800000 | F22: =C3 -> 3 | G22: =E22*F22 -> 14400000 | I22: =G22/(1-H22) -> 14400000 | M22: =I22+I26+I27+I18+SUM('Manpower Cost'!T18:T21) -> 27410000
C23: Ongoing Operations, Support and Maintenance | D23: Per Year | E23: ='Manpower Cost'!S8+'Manpower Cost'!O18 -> 751000 | F23: 3 | G23: =L7 -> 1923000 | I23: =G23 -> 1923000
D24: Total Subscription & PMO Cost | G24: =G22+G23 -> 16323000 | I24: =I22+I23 -> 16323000
B25: AMC | C25: AMC Cost from 2nd year | D25: Per Year | E25: =G13*C4 -> 4268150 | F25: 2 | G25: =E25*F25 -> 8536300 | I25: =G25 -> 8536300
B26: Track and Trace | C26: Track and Trace API- Calculation based on 200 Trips Per day | D26: Per Year | E26: ='Track and Trace'!C5*35 -> 2520000 | F26: 3 | G26: =E26*F26 -> 7560000 | I26: =G26 -> 7560000
B27: Command centre Inteface | C27: Command and Centre Interface | D27: Per Year | E27: =50000*12 -> 600000 | F27: 3 | G27: =E27*F27 -> 1800000 | I27: =G27 -> 1800000
C28: Total Cost of the Project for 3 Years | G28: =G20+G24+G25+G26+G27 -> 55425530 | H28: =1-G28/I28 -> 0 | I28: =I20+I24+I25+I26+I27 -> 55425530
G31: s | K31: `

Sheet Software charges
A1: Item Description | B1: Quote
A2: Platform subscription | B2: =150000*36 -> 5400000
A3: ERP Integration | B3: 800000 | E3: Onetime | F3: =B3+B4+B5 -> 3480000 | H3: Trips | J3: TMS
A4: Implementation | B4: 2200000 | E4: opex | F4: =B2+B6+B7 -> 9123000 | G4: =F4/33000000 -> 0.27645455 | H4: =33000000/30 -> 1100000 | J4: =0.15*11000000 -> 1650000 | L4: =33000000/22 -> 1500000 | N4: =3480000/33000000 -> 0.10545455
A5: Hypercare | B5: 480000 | H5: =H4*35 -> 38500000 | J5: =J4/12 -> 137500 | L5: =L4*20 -> 30000000
A6: Operations | B6: =('Manpower Cost'!S8*3)+('Manpower Cost'!O18*2.5) -> 1923000 | H6: =H5/33000000 -> 1.1666667 | L6: =L5/33000000 -> 0.90909091
A7: Command centre | B7: 1800000
A8: Total | B8: =SUM(B2:B7) -> 12603000 | H8: Trips/month | L8: Trips/month
A9: Track & Trace Per Trip | B9: Rs.35/- | H9: =H4/36 -> 30555.556 | L9: =L4/36 -> 41666.667
H14: 5000 | I14: 40 | J14: 36 | K14: =H14*I14*J14 -> 7200000
B15: Fleetx Present
A16: Software | B16: =11000000*0.15 -> 1650000 | G16: With our Device | H16: 5000 | I16: 185 | J16: =H16*I16*36 -> 33300000 | N16: =0.1*11000000 -> 1100000
A17: maintenance | B17: =400*5000 -> 2000000 | J17: =J16/33000000 -> 1.0090909
A18: Manpower | B18: =300000*12 -> 3600000 | G18: Without device including manpower | H18: 5000 | I18: 100 | J18: =H18*I18*36 -> 18000000 | K18: =300000*36 -> 10800000
B19: =SUM(B16:B18) -> 7250000 | J19: =J18/33000000 -> 0.54545455 | K19: =J18-K18 -> 7200000
K20: =K19/33000000 -> 0.21818182
H22: 5000 | I22: 100 | J22: =H22*I22*12 -> 6000000

Sheet Sheet7
C1: Manmohan | D1: Proposal | F1: Revenue | I1: Ton/year | J1: 11000000
B2: ITMS | C2: =(150000*12)/11000000 -> 0.16363636 | D2: 0.32 | F2: =D2*$J$1 -> 3520000 | G2: 0.4
B3: Track and trace | C3: 0.21 | D3: 0.25 | F3: =D3*$J$1 -> 2750000 | G3: 0.29
B4: MCT Lite | C4: =0.05 -> 0.05 | D4: 0.05 | F4: =D4*$J$1 -> 550000 | G4: 0.08
B5: Risk Mitigation | C5: 0.08 | D5: 0.08 | F5: =D5*$J$1 -> 880000 | G5: 0.08
D6: 0.69 | E6: Per ton | F6: =SUM(F2:F5) -> 7700000
B8: 1500 per device GPS
B9: Rs.600 maintenance
B10: Manpower- 30000/month/person
B11: Minimum billing of 11MTPA per year | G11: 0.85

Sheet Hardware
A3: Hardware | B3: Quantity | C3: Spare | D3: Unit Price | E3: Hardware Cost | F3: Spare Cost | G3: Total hardware Quantity | H3: Total Price | I3: Available at site | J3: Net Hardware | K3: Unit Price | L3: Net Cost
A4: ANPR Camera | B4: 20 | C4: 2 | D4: =VLOOKUP(A4,Master!$D$1:$E$14,2,0) -> 48000 | E4: =B4*D4 -> 960000 | F4: =C4*D4 -> 96000 | G4: =(B4+C4) -> 22 | H4: =D4*G4 -> 1056000 | I4: 2 | J4: =G4-I4 -> 20 | K4: =D4 -> 48000 | L4: =K4*J4 -> 960000
A5: AT Controller | B5: 18 | C5: 2 | D5: =VLOOKUP(A5,Master!$D$1:$E$14,2,0) -> 16000 | E5: =B5*D5 -> 288000 | F5: =C5*D5 -> 32000 | G5: =(B5+C5) -> 20 | H5: =D5*G5 -> 320000 | I5: 3 | J5: =G5-I5 -> 17 | K5: =D5 -> 16000 | L5: =K5*J5 -> 272000
A6: Biometric Device | B6: 20 | C6: 1 | D6: =VLOOKUP(A6,Master!$D$1:$E$14,2,0) -> 21000 | E6: =B6*D6 -> 420000 | F6: =C6*D6 -> 21000 | G6: =(B6+C6) -> 21 | H6: =D6*G6 -> 441000 | I6: 0 | J6: =G6-I6 -> 21 | K6: =D6 -> 21000 | L6: =K6*J6 -> 441000
A7: Boom Barrier | B7: 38 | C7: 2 | D7: =VLOOKUP(A7,Master!$D$1:$E$14,2,0) -> 290000 | E7: =B7*D7 -> 11020000 | F7: =C7*D7 -> 580000 | G7: =(B7+C7) -> 40 | H7: =D7*G7 -> 11600000 | I7: 0 | J7: =G7-I7 -> 40 | K7: =D7 -> 290000 | L7: =K7*J7 -> 11600000
A8: Handheld RFID Reader | B8: 4 | C8: 1 | D8: =VLOOKUP(A8,Master!$D$1:$E$14,2,0) -> 66000 | E8: =B8*D8 -> 264000 | F8: =C8*D8 -> 66000 | G8: =(B8+C8) -> 5 | H8: =D8*G8 -> 330000 | I8: 0 | J8: =G8-I8 -> 5 | K8: =D8 -> 66000 | L8: =K8*J8 -> 330000
A9: Industrial Grade Tablet | B9: 14 | C9: 1 | D9: =VLOOKUP(A9,Master!$D$1:$E$14,2,0) -> 41000 | E9: =B9*D9 -> 574000 | F9: =C9*D9 -> 41000 | G9: =(B9+C9) -> 15 | H9: =D9*G9 -> 615000 | I9: 0 | J9: =G9-I9 -> 15 | K9: =D9 -> 41000 | L9: =K9*J9 -> 615000
A10: LED Display | B10: 30 | C10: 1 | D10: =VLOOKUP(A10,Master!$D$1:$E$14,2,0) -> 14000 | E10: =B10*D10 -> 420000 | F10: =C10*D10 -> 14000 | G10: =(B10+C10) -> 31 | H10: =D10*G10 -> 434000 | I10: 1 | J10: =G10-I10 -> 30 | K10: =D10 -> 14000 | L10: =K10*J10 -> 420000
A11: PA System | B11: 24 | C11: 1 | D11: =VLOOKUP(A11,Master!$D$1:$E$14,2,0) -> 12000 | E11: =B11*D11 -> 288000 | F11: =C11*D11 -> 12000 | G11: =(B11+C11) -> 25 | H11: =D11*G11 -> 300000 | I11: 0 | J11: =G11-I11 -> 25 | K11: =D11 -> 12000 | L11: =K11*J11 -> 300000
A12: Printer | B12: 6 | C12: 1 | D12: =VLOOKUP(A12,Master!$D$1:$E$14,2,0) -> 22000 | E12: =B12*D12 -> 132000 | F12: =C12*D12 -> 22000 | G12: =(B12+C12) -> 7 | H12: =D12*G12 -> 154000 | I12: 0 | J12: =G12-I12 -> 7 | K12: =D12 -> 22000 | L12: =K12*J12 -> 154000
A13: Proximity Sensor | B13: 36 | C13: 2 | D13: =VLOOKUP(A13,Master!$D$1:$E$14,2,0) -> 5700 | E13: =B13*D13 -> 205200 | F13: =C13*D13 -> 11400 | G13: =(B13+C13) -> 38 | H13: =D13*G13 -> 216600 | I13: 0 | J13: =G13-I13 -> 38 | K13: =D13 -> 5700 | L13: =K13*J13 -> 216600
A14: RFID Reader | B14: 38 | C14: 2 | D14: =VLOOKUP(A14,Master!$D$1:$E$14,2,0) -> 27000 | E14: =B14*D14 -> 1026000 | F14: =C14*D14 -> 54000 | G14: =(B14+C14) -> 40 | H14: =D14*G14 -> 1080000 | I14: 0 | J14: =G14-I14 -> 40 | K14: =D14 -> 27000 | L14: =K14*J14 -> 1080000
A15: Smart Camera | B15: 40 | C15: 2 | D15: =VLOOKUP(A15,Master!$D$1:$E$14,2,0) -> 7000 | E15: =B15*D15 -> 280000 | F15: =C15*D15 -> 14000 | G15: =(B15+C15) -> 42 | H15: =D15*G15 -> 294000 | I15: 0 | J15: =G15-I15 -> 42 | K15: =D15 -> 7000 | L15: =K15*J15 -> 294000
A16: Traffic Signal | B16: 27 | C16: 2 | D16: =VLOOKUP(A16,Master!$D$1:$E$14,2,0) -> 8000 | E16: =B16*D16 -> 216000 | F16: =C16*D16 -> 16000 | G16: =(B16+C16) -> 29 | H16: =D16*G16 -> 232000 | I16: 0 | J16: =G16-I16 -> 29 | K16: =D16 -> 8000 | L16: =K16*J16 -> 232000
A17: Total | B17: =SUM(B4:B16) -> 315 | C17: =SUM(C4:C16) -> 20 | E17: =SUM(E4:E16) -> 16093200 | F17: =SUM(F4:F16) -> 979400 | G17: =SUM(G4:G16) -> 335 | H17: =SUM(H4:H16) -> 17072600 | I17: =SUM(I4:I16) -> 6 | J17: =SUM(J4:J16) -> 329 | L17: =SUM(L4:L16) -> 16914600

Sheet Manpower Cost
A1: Phase 1
B3: Installation, Training & Configuration Cost Current (a) | J3: Project Management Cost ( c)
B4: Type of Manpower | C4: Count per shift | D4: Nos. of shifts | E4: Cost per unit | F4: Duration in Months | G4: Total | J4: Type of Manpower | K4: Type | L4: Travel Allowance | M4: Travel Cost | N4: Stay Cost per Day | O4: Days per trip | Q4: Frequency (Annually) | S4: Total
B5: PM | C5: 1 | D5: 1 | E5: 100000 | F5: 4 | G5: =C5*D5*E5*F5 -> 400000 | J5: Project Manager | K5: Per Year | L5: =VLOOKUP(J5,[1]Master!$A$57:$E$61,2,FALSE) -> 2000 | M5: =VLOOKUP(J5,[1]Master!$A$57:$E$61,3,FALSE) -> 20000 | N5: 3500 | O5: 2 | Q5: 1 | S5: =(Q5*O5*L5)+(M5*Q5)+(N5*O5*Q5) -> 31000
B6: Hardware Engineers | C6: 8 | D6: 0 | E6: 40000 | F6: 4 | G6: 0 | J6: Project Coordinator | K6: Per Year | L6: =VLOOKUP(J6,[1]Master!$A$57:$E$61,2,FALSE) -> 1500 | M6: =VLOOKUP(J6,[1]Master!$A$57:$E$61,3,FALSE) -> 20000 | N6: =VLOOKUP(J6,[1]Master!$A$57:$E$61,4,FALSE) -> 3500 | O6: 2 | Q6: 1 | S6: =(Q6*O6*L6)+(M6*Q6)+(N6*O6*Q6) -> 30000
B7: Software Engineers | C7: 6 | D7: 1 | E7: 75000 | F7: 4 | G7: =C7*D7*E7*F7 -> 1800000 | J7: Misc Travel | K7: Per Year | L7: =VLOOKUP(J7,[1]Master!$A$57:$E$61,2,FALSE) -> 1500 | M7: =VLOOKUP(J7,[1]Master!$A$57:$E$61,3,FALSE) -> 20000 | N7: 3500 | O7: 2 | Q7: 1 | S7: =(Q7*O7*L7)+(M7*Q7)+(N7*O7*Q7) -> 30000
C8: =C5*D5+C6*D6+C7*D7 -> 7 | F8: Total | G8: =SUM(G5:G7) -> 2200000 | Q8: Total | S8: =SUM(S5:S7) -> 91000
B12: Operations-Onsite Manpower, Support & Maintenance Cost (Hyper Care) | J12: Operations-Onsite Manpower, Support & Maintenance Cost current
B13: Type of Manpower | C13: Count per shift | D13: Nos. of shifts | E13: Cost per unit | F13: Duration in Months | G13: Total | J13: Type of Manpower | K13: Count per shift | L13: Nos. of shifts | M13: Cost per unit | N13: Duration in Months | O13: Total
B14: Sr. CS | C14: 1 | D14: 1 | E14: 50000 | F14: 6 | G14: =C14*D14*E14*F14 -> 300000 | J14: Sr. CS | K14: 0.5 | L14: 1 | M14: 50000 | N14: 12 | O14: =K14*L14*M14*N14 -> 300000
B15: Support Engineers (Mines) | C15: 2 | D15: 0 | E15: 30000 | F15: 6 | G15: =C15*D15*E15*F15 -> 0 | J15: Support Engineers (Mines) | K15: 2 | L15: 4 | M15: 30000 | N15: 0 | O15: =K15*L15*M15*N15 -> 0
B16: Support Engineers (Dabuna) | C16: 1 | D16: 0 | E16: 30000 | F16: 6 | G16: =C16*D16*E16*F16 -> 0 | J16: Support Engineers (Dabuna) | K16: 1 | L16: 4 | M16: 30000 | N16: 0 | O16: =K16*L16*M16*N16 -> 0
B17: MIS | C17: 1 | D17: 1 | E17: 30000 | F17: 6 | G17: =C17*D17*E17*F17 -> 180000 | J17: MIS | K17: 1 | L17: 1 | M17: 30000 | N17: 12 | O17: =K17*L17*M17*N17 -> 360000
F18: Total | G18: =SUM(G14:G17) -> 480000 | N18: Total | O18: =SUM(O14:O17) -> 660000 | T18: 1800000 | U18: implementation
T19: 400000
B20: Command centre | T20: 400000 | U20: travel
T21: 450000 | U21: cs

Sheet Sheet2

Sheet Sheet4

Sheet BOQ
A1: # | B1: Stage | C1: Hardware | D1: Qty/Unit | E1: Units (Sagasahi) | F1: Units (Thakurani) | G1: Units (Dabuna) | H1: Total Hardware
A2: 1 | B2: Parking In | C2: Boom Barrier | D2: 1 | E2: 2 | F2: 1 | G2: 0 | H2: =(F2+E2)*D2 -> 3
C3: RFID Reader | D3: 1 | E3: 2 | F3: 1 | G3: 0 | H3: =(F3+E3)*D3 -> 3
C4: PA System | D4: 1 | E4: 2 | F4: 1 | G4: 0 | H4: =(F4+E4)*D4 -> 3
A5: 2 | B5: Parking | C5: Industrial Grade Tablet | D5: 2 | E5: 2 | F5: 1 | G5: 0 | H5: =(F5+E5)*D5 -> 6
A6: 3 | B6: Parking Out | C6: Boom Barrier | D6: 1 | E6: 2 | F6: 1 | G6: 0 | H6: =(F6+E6)*D6 -> 3
C7: RFID Reader | D7: 1 | E7: 2 | F7: 1 | G7: 0 | H7: =(F7+E7)*D7 -> 3
C8: PA System | D8: 1 | E8: 2 | F8: 1 | G8: 0 | H8: =(F8+E8)*D8 -> 3
A9: 4 | B9: Gate In | C9: RFID Reader | D9: 1 | E9: 2 | F9: 1 | G9: 0 | H9: =(F9+E9)*D9 -> 3
C10: Industrial Grade Tablet | D10: 1 | E10: 2 | F10: 1 | G10: 0 | H10: =(F10+E10)*D10 -> 3
C11: ANPR Camera | D11: 1 | E11: 2 | F11: 1 | G11: 0 | H11: =(F11+E11)*D11 -> 3
C12: Boom Barrier | D12: 1 | E12: 2 | F12: 1 | G12: 0 | H12: =(F12+E12)*D12 -> 3
C13: Smart Camera | D13: 2 | E13: 2 | F13: 1 | G13: 0 | H13: =(F13+E13)*D13 -> 6
C14: LED Display | D14: 1 | E14: 2 | F14: 1 | G14: 0 | H14: =(F14+E14)*D14 -> 3
C15: PA System | D15: 1 | E15: 2 | F15: 1 | G15: 0 | H15: =(F15+E15)*D15 -> 3
C16: AT Controller | D16: 1 | E16: 2 | F16: 1 | G16: 0 | H16: =(F16+E16)*D16 -> 3
C17: Traffic Signal | D17: 1 | E17: 2 | F17: 1 | G17: 0 | H17: =(F17+E17)*D17 -> 3
C18: Biometric Device | D18: 1 | E18: 2 | F18: 1 | G18: 0 | H18: =(F18+E18)*D18 -> 3
A19: 5 | B19: Weigh Bridge | C19: Boom Barrier | D19: 2 | E19: 6 | F19: 6 | G19: 0 | H19: =(F19+E19)*D19 -> 24
C20: PA System | D20: 1 | E20: 6 | F20: 6 | G20: 0 | H20: =(F20+E20)*D20 -> 12
C21: Traffic Signal | D21: 2 | E21: 6 | F21: 6 | G21: 0 | H21: =(F21+E21)*D21 -> 24
C22: RFID Reader | D22: 2 | E22: 6 | F22: 6 | G22: 0 | H22: =(F22+E22)*D22 -> 24
C23: AT Controller | D23: 1 | E23: 6 | F23: 6 | G23: 0 | H23: =(F23+E23)*D23 -> 12
C24: Proximity Sensor | D24: 3 | E24: 6 | F24: 6 | G24: 0 | H24: =(F24+E24)*D24 -> 36
C25: Smart Camera | D25: 2 | E25: 6 | F25: 6 | G25: 0 | H25: =(F25+E25)*D25 -> 24
C26: ANPR Camera | D26: 1 | E26: 6 | F26: 6 | G26: 0 | H26: =(F26+E26)*D26 -> 12
C27: LED Display | D27: 2 | E27: 6 | F27: 6 | G27: 0 | H27: =(F27+E27)*D27 -> 24
C28: Biometric Device | D28: 1 | E28: 6 | F28: 6 | G28: 0 | H28: =(F28+E28)*D28 -> 12
A29: 6 | B29: Enroute | C29: Traffic Signal/ Display/ RFID Reader/ Mobile Apllication | G29: 0 | H29: Hardware depends on the length of the road and activities to be performed
A30: 7 | B30: Loading Point | C30: Handheld RFID Reader | D30: 1 | E30: 2 | F30: 2 | G30: 0 | H30: =(F30+E30)*D30 -> 4
A31: 8 | B31: Gate out | C31: Industrial Grade Tablet | D31: 1 | E31: 2 | F31: 1 | G31: 0 | H31: =(F31+E31)*D31 -> 3
C32: Boom Barrier | D32: 1 | E32: 2 | F32: 1 | G32: 0 | H32: =(F32+E32)*D32 -> 3
C33: ANPR Camera | D33: 1 | E33: 2 | F33: 1 | G33: 0 | H33: =(F33+E33)*D33 -> 3
C34: RFID Reader | D34: 1 | E34: 2 | F34: 1 | G34: 0 | H34: =(F34+E34)*D34 -> 3
C35: Printer | D35: 2 | E35: 2 | F35: 1 | G35: 0 | H35: =(F35+E35)*D35 -> 6
C36: AT Controller | D36: 1 | E36: 2 | F36: 1 | G36: 0 | H36: =(F36+E36)*D36 -> 3
C37: PA System | D37: 1 | E37: 2 | F37: 1 | G37: 0 | H37: =(F37+E37)*D37 -> 3
C38: Biometric Device | D38: 1 | E38: 2 | F38: 1 | G38: 0 | H38: =(F38+E38)*D38 -> 3
C39: Smart Camera | D39: 2 | E39: 2 | F39: 1 | G39: 0 | H39: =(F39+E39)*D39 -> 6
C40: LED Display | D40: 1 | E40: 2 | F40: 1 | G40: 0 | H40: =(F40+E40)*D40 -> 3
...

Sheet Track and Trace
B2: Per day Trips | C2: 200
B3: Per trip | C3: 35
B4: Monthly | C4: =C2*30 -> 6000
B5: yearly | C5: =C4*12 -> 72000
B6: 3 years | C6: =C5*3 -> 216000
B7: Total cost | C7: =C6*C3 -> 7560000

Sheet Master
D1: Hardware | E1: Price
A2: Boom Barrier | D2: Boom Barrier | E2: 290000
A3: ANPR Camera | D3: ANPR Camera | E3: 48000
A4: RFID Reader | D4: RFID Reader | E4: 27000
A5: Handheld RFID Reader | D5: Handheld RFID Reader | E5: 66000
A6: Industrial Grade Tablet | D6: Industrial Grade Tablet | E6: 41000
A7: Smart Camera | D7: Smart Camera | E7: 7000
A8: LED Display | D8: LED Display | E8: 14000
A9: PA System | D9: PA System | E9: 12000
A10: Biometric Device | D10: Biometric Device | E10: 21000
A11: Proximity Sensor | D11: Proximity Sensor | E11: 5700
A12: Printer | D12: Printer | E12: 22000
A13: AT Controller | D13: AT Controller | E13: 16000
A14: Traffic Signal | D14: Traffic Signal | E14: 8000

Sheet Copy
A2: Model | B2: Items | C2: Details | D2: Type | E2: Cost for 3 Years
A3: One Time Cost | B3: Hardware Cost | C3: Hardware - Mining Automation | D3: One Time | E3: 23901640
B4: Implementation Cost | C4: Installation, Training & Configuration | D4: One Time | E4: 4640000
C5: Hypercare- Onsite Manpower, Project Management, Support & Maintenance | D5: One Time | E5: 3520000
C6: ERP Integration | D6: One Time | E6: 800000
C7: Total Installation, Setup,Hyper Care & API Development Cost | E7: 8960000
D8: Total One Time Cost | E8: 32861640
B9: Annual Subscription fee | C9: Platform Subscription Fee | D9: Per Year | E9: 18360000
C10: Ongoing Operations, Support and Maintenance | D10: Per Year | E10: 13539000
D11: Total Subscription & PMO Cost | E11: 31899000
B12: AMC | C12: AMC Cost from 2nd year | D12: Per Year | E12: 8536300
B13: Track and Trace | C13: Track and Trace API- Calculation based on 200 Trips Per day | D13: Per Year | E13: 7560000
B14: Command centre Inteface | C14: Command Centre Interface | D14: Per Year | E14: 1800000
C15: Total Cost of the Project for 3 Years | E15: 82656940
G18: `
